<?xml version="1.0" encoding="UTF-8" ?>
<robot name="scara_arm">
    <link name="world" />
    <joint name="world_to_base" type="fixed">
        <parent link="world" />
        <child link="base" />
        <origin xyz="0 0 0.0175" rpy="0 0 0" />
    </joint>
    <link name="base">
        <visual>
            <origin xyz="0 0 0" rpy="0 0 0" />
            <geometry>
                <box size="0.2 0.2 0.035" />
            </geometry>
            <material name="orange">
                <color rgba="0.8 0.4 0.0 1.0" />
            </material>
        </visual>
        <collision>
            <origin xyz="0 0 0" rpy="0 0 0" />
            <geometry>
                <box size="0.2 0.2 0.035" />
            </geometry>
        </collision>
        <inertial>
            <mass value="0.1" />
            <origin xyz="0 0 0" rpy="0 0 0" />
            <inertia ixx="0.03" iyy="0.03" izz="0.03" ixy="0.0" ixz="0.0" iyz="0.0" />
        </inertial>
    </link>
    <gazebo reference="base">
    	 <material>Gazebo/Orange</material>
    </gazebo>  
    
    <link name="base_link">
        <visual>
            <origin xyz="0 0 0" rpy="0 0 0" />
            <geometry>
                <cylinder length="0.4" radius="0.06" />
            </geometry>
            <material name="orange">
                <color rgba="0.8 0.4 0.0 1.0" />
            </material>
        </visual>
        <collision>
            <origin xyz="0 0 0" rpy="0 0 0" />
            <geometry>
                <cylinder length="0.4" radius="0.06" />
            </geometry>
        </collision>
        <inertial>
            <mass value="0.1" />
            <origin xyz="0 0 0" rpy="0 0 0" />
            <inertia ixx="0.03" iyy="0.03" izz="0.03" ixy="0.0" ixz="0.0" iyz="0.0" />
        </inertial>
    </link>
    <gazebo reference="base_link">
    	 <material>Gazebo/Orange</material>
    </gazebo>     
    <joint name="fixed_joint" type="fixed">
        <parent link="base" />
        <child link="base_link" />
        <origin xyz="0 0 0.2" rpy="0 0 0" />
    </joint>
    <link name="link1">
        <visual>
            <origin xyz="-0.09 0 0.03" rpy="0 0 0" />
            <geometry>
                <box size="0.3 0.1 0.06" />
            </geometry>
            <material name="orange">
                <color rgba="0.8 0.4 0.0 1.0" />
            </material>
        </visual>
        <collision>
            <origin xyz="-0.09 0 0.03" rpy="0 0 0" />
            <geometry>
                <box size="0.3 0.1 0.06" />
            </geometry>
        </collision>
        <inertial>
            <mass value="0.1" />
            <origin xyz="0 0 0" rpy="0 0 0" />
            <inertia ixx="0.03" iyy="0.03" izz="0.03" ixy="0.0" ixz="0.0" iyz="0.0" />
        </inertial>
    </link>
    <gazebo reference="link1">
    	 <material>Gazebo/Orange</material>
    </gazebo>    
    <joint name="link1_joint" type="revolute">
        <parent link="base_link" />
        <child link="link1" />
        <origin xyz="0 0 0.2" rpy="0 0 0" />
        <axis xyz="0 0 1" />
        <limit lower="-1.57" upper="1.57" effort="100" velocity="100" />
    </joint>
    <link name="link2">
        <visual>
            <origin xyz="-0.09 0 -0.03" rpy="0 0 0" />
            <geometry>
                <box size="0.3 0.1 0.06" />
            </geometry>
            <material name="orange">
                <color rgba="0.8 0.4 0.0 1.0" />
            </material>
        </visual>
        <collision>
            <origin xyz="-0.09 0 -0.03" rpy="0 0 0" />
            <geometry>
                <box size="0.3 0.1 0.06" />
            </geometry>
        </collision>
        <inertial>
            <mass value="0.1" />
            <origin xyz="0 0 0" rpy="0 0 0" />
            <inertia ixx="0.03" iyy="0.03" izz="0.03" ixy="0.0" ixz="0.0" iyz="0.0" />
        </inertial>
    </link>
    <gazebo reference="link2">
    	 <material>Gazebo/Orange</material>
    </gazebo>      
    <joint name="link2_joint" type="revolute">
        <parent link="link1" />
        <child link="link2" />
        <origin xyz="-0.18 0 0" rpy="0 0 0" />
        <axis xyz="0 0 1" />
        <limit lower="-1.57" upper="1.57" effort="100" velocity="100" />
    </joint>
    <link name="link3">
        <visual>
            <origin xyz="0 0 0.1" rpy="0 0 0" />
            <geometry>
                <cylinder length="0.2" radius="0.035" />
            </geometry>
            <material name="orange">
                <color rgba="0.8 0.4 0.0 1.0" />
            </material>
        </visual>
        <collision>
            <origin xyz="0 0 0.1" rpy="0 0 0" />
            <geometry>
                <cylinder length="0.2" radius="0.035" />
            </geometry>
        </collision>
        <inertial>
            <mass value="0.1" />
            <origin xyz="0 0 0" rpy="0 0 0" />
            <inertia ixx="0.03" iyy="0.03" izz="0.03" ixy="0.0" ixz="0.0" iyz="0.0" />
        </inertial>
    </link>
    <gazebo reference="link3">
    	 <material>Gazebo/Orange</material>
    </gazebo>        
    <joint name="link3_joint" type="prismatic">
        <parent link="link2" />
        <child link="link3" />
        <origin xyz="-0.2 0 0" rpy="0 0 0" />
        <axis xyz="0 0 1" />
        <limit lower="-0.22" upper="-0.08" effort="100" velocity="1" />
    </joint>
    <link name="connector">
        <visual>
            <origin xyz="0 0 -0.04" rpy="0 0 0" />
            <geometry>
                <cylinder length="0.08" radius="0.01" />
            </geometry>
            <material name="orange">
                <color rgba="0.8 0.4 0.0 1.0" />
            </material>
        </visual>
        <collision>
            <origin xyz="0 0 -0.04" rpy="0 0 0" />
            <geometry>
                <cylinder length="0.08" radius="0.01" />
            </geometry>
        </collision>
        <inertial>
            <mass value="0.1" />
            <origin xyz="0 0 0" rpy="0 0 0" />
            <inertia ixx="0.03" iyy="0.03" izz="0.03" ixy="0.0" ixz="0.0" iyz="0.0" />
        </inertial>
    </link>
    <gazebo reference="connector">
    	 <material>Gazebo/DarkGrey</material>
    </gazebo>     
    <joint name="connector_joint" type="fixed">
        <parent link="link3" />
        <child link="connector" />
        <origin xyz="0 0 0" rpy="0 0 -1.57" />
    </joint>
    <link name="wrist">
        <visual>
            <origin xyz="0 0 -0.0175" rpy="0 0 0" />
            <geometry>
                <box size="0.1 0.1 0.035" />
            </geometry>
            <material name="orange">
                <color rgba="0.8 0.4 0.0 1.0" />
            </material>
        </visual>
        <collision>
            <origin xyz="0 0 -0.0175" rpy="0 0 0" />
            <geometry>
                <box size="0.1 0.1 0.035" />
            </geometry>
        </collision>
        <inertial>
            <mass value="0.1" />
            <origin xyz="0 0 0" rpy="0 0 0" />
            <inertia ixx="0.03" iyy="0.03" izz="0.03" ixy="0.0" ixz="0.0" iyz="0.0" />
        </inertial>
    </link>
    <gazebo reference="wrist">
    	 <material>Gazebo/DarkGrey</material>
    </gazebo>     
    <joint name="wrist_joint" type="fixed">
        <parent link="connector" />
        <child link="wrist" />
        <origin xyz="0 0 -0.08" rpy="0 0 0" />
    </joint>
    <link name="gripper_link1">
        <visual>
            <origin xyz="0 0 -0.03" rpy="0 0 0" />
            <geometry>
                <box size="0.01 0.03 0.06" />
            </geometry>
            <material name="orange">
                <color rgba="0.8 0.4 0.0 1.0" />
            </material>
        </visual>
        <collision>
            <origin xyz="0 0 -0.03" rpy="0 0 0" />
            <geometry>
                <box size="0.01 0.03 0.06" />
            </geometry>
        </collision>
        <inertial>
            <mass value="0.1" />
            <origin xyz="0 0 0" rpy="0 0 0" />
            <inertia ixx="0.03" iyy="0.03" izz="0.03" ixy="0.0" ixz="0.0" iyz="0.0" />
        </inertial>
    </link>
    <gazebo reference="gripper_link1">
    	 <material>Gazebo/DarkGrey</material>
    </gazebo>      
    <joint name="gripper_joint1" type="prismatic">
        <parent link="wrist" />
        <child link="gripper_link1" />
        <origin xyz="0 0 -0.035" rpy="0 0 0" />
        <limit lower="0.01" upper="0.04" effort="100" velocity="1" />
    </joint>
    <link name="gripper_link2">
        <visual>
            <origin xyz="0 0 -0.03" rpy="0 0 0" />
            <geometry>
                <box size="0.01 0.03 0.06" />
            </geometry>
            <material name="orange">
                <color rgba="0.8 0.4 0.0 1.0" />
            </material>
        </visual>
        <collision>
            <origin xyz="0 0 -0.03" rpy="0 0 0" />
            <geometry>
                <box size="0.01 0.03 0.06" />
            </geometry>
        </collision>
        <inertial>
            <mass value="0.1" />
            <origin xyz="0 0 0" rpy="0 0 0" />
            <inertia ixx="0.03" iyy="0.03" izz="0.03" ixy="0.0" ixz="0.0" iyz="0.0" />
        </inertial>
    </link>
    <gazebo reference="gripper_link2">
    	 <material>Gazebo/DarkGrey</material>
    </gazebo>        
    <joint name="gripper_joint2" type="prismatic">
        <parent link="wrist" />
        <child link="gripper_link2" />
        <origin xyz="0 0 -0.035" rpy="0 0 0" />
        <limit lower="-0.04" upper="-0.01" effort="100" velocity="1" />
    </joint>
    
    
  <!-- Camera -->
  <link name="camera_link">
	<collision>
  	<origin xyz="0 0 0" rpy="0 0 0"/>
  	<geometry>
	<box size="0.02 0.02 0.02"/>
  	</geometry>
	</collision>

	<visual>
  	<origin xyz="0 0 0" rpy="0 0 0"/>
  	<geometry>
	<box size="0.02 0.02 0.02"/>
  	</geometry>
  	<material name="red"/>
	</visual>

	<inertial>
  	<mass value="1e-5" />
  	<origin xyz="0 0 0" rpy="0 0 0"/>
  	<inertia ixx="1e-6" ixy="0" ixz="0" iyy="1e-6" iyz="0" izz="1e-6" />
	</inertial>
  </link>
 
  <joint name="camera_joint" type="fixed">
	<axis xyz="0 1 0" />
	<origin xyz="0 -0.063 -0.04" rpy="0 1.57 0"/>
	<parent link="wrist"/>
	<child link="camera_link"/>
  </joint>
    <gazebo reference="camera_link">
    	 <material>Gazebo/DarkGrey</material>
    </gazebo> 
<!-- camera -->
   <gazebo reference="camera_link">
	<sensor type="camera" name="camera1">
  	<update_rate>30.0</update_rate>
  	<camera name="head">
    	<horizontal_fov>1.3962634</horizontal_fov>
    	<image>
      	<width>800</width>
      	<height>800</height>
      	<format>R8G8B8</format>
    	</image>
    	<clip>
      	<near>0.02</near>
      	<far>300</far>
    	</clip>
    	<noise>
      	<type>gaussian</type>
      	<!-- Noise is sampled independently per pixel on each frame.
           	That pixel's noise value is added to each of its color
           	channels, which at that point lie in the range [0,1]. -->
      	<mean>0.0</mean>
      	<stddev>0.007</stddev>
    	</noise>
  	</camera>
  	<plugin name="camera_controller" filename="libgazebo_ros_camera.so">
    	<alwaysOn>true</alwaysOn>
    	<updateRate>0.0</updateRate>
    	<cameraName>scara/camera1</cameraName>
    	<imageTopicName>image_raw</imageTopicName>
    	<cameraInfoTopicName>camera_info</cameraInfoTopicName>
    	<frameName>camera_link</frameName>
    	<hackBaseline>0.07</hackBaseline>
    	<distortionK1>0.0</distortionK1>
    	<distortionK2>0.0</distortionK2>
    	<distortionK3>0.0</distortionK3>
    	<distortionT1>0.0</distortionT1>
    	<distortionT2>0.0</distortionT2>
  	</plugin>
	</sensor>
  </gazebo>
    
    <transmission name="trans_link1_joint">
        <type>transmission_interface/SimpleTransmission</type>
        <joint name="link1_joint">
            <hardwareInterface>hardware_interface/PositionJointInterface</hardwareInterface>
        </joint>
        <actuator name="link1_joint_motor">
            <hardwareInterface>hardware_interface/PositionJointInterface</hardwareInterface>
            <mechanicalReduction>1</mechanicalReduction>
        </actuator>
    </transmission>
    <transmission name="trans_link2_joint">
        <type>transmission_interface/SimpleTransmission</type>
        <joint name="link2_joint">
            <hardwareInterface>hardware_interface/PositionJointInterface</hardwareInterface>
        </joint>
        <actuator name="link2_joint_motor">
            <hardwareInterface>hardware_interface/PositionJointInterface</hardwareInterface>
            <mechanicalReduction>1</mechanicalReduction>
        </actuator>
    </transmission>
    <transmission name="trans_link3_joint">
        <type>transmission_interface/SimpleTransmission</type>
        <joint name="link3_joint">
            <hardwareInterface>hardware_interface/PositionJointInterface</hardwareInterface>
        </joint>
        <actuator name="link3_joint_motor">
            <hardwareInterface>hardware_interface/PositionJointInterface</hardwareInterface>
            <mechanicalReduction>1</mechanicalReduction>
        </actuator>
    </transmission>
    <transmission name="trans_gripper_joint1">
        <type>transmission_interface/SimpleTransmission</type>
        <joint name="gripper_joint1">
            <hardwareInterface>hardware_interface/EffortJointInterface</hardwareInterface>
        </joint>
        <actuator name="gripper_joint1_motor">
            <hardwareInterface>hardware_interface/EffortJointInterface</hardwareInterface>
            <mechanicalReduction>1</mechanicalReduction>
        </actuator>
    </transmission>
    <transmission name="trans_gripper_joint2">
        <type>transmission_interface/SimpleTransmission</type>
        <joint name="gripper_joint2">
            <hardwareInterface>hardware_interface/EffortJointInterface</hardwareInterface>
        </joint>
        <actuator name="gripper_joint2_motor">
            <hardwareInterface>hardware_interface/EffortJointInterface</hardwareInterface>
            <mechanicalReduction>1</mechanicalReduction>
        </actuator>
    </transmission>
    <gazebo>
        <plugin name="gazebo_ros_control" filename="libgazebo_ros_control.so">
            <robotNamespace>/</robotNamespace>
        </plugin>
    </gazebo>
</robot>

